Workbook

Sheet Inicio
A1: SIMULADOR DE INVESTIMENTOS Ferramenta de apoio à conversa com o cliente
A5: O motor faz contas sofisticadas — mês a mês, com imposto, come-cotas, custos e inflação. O painel mostra pouca coisa: quanto entra, por quanto tempo, quanto pode virar, quando dá para retirar e qual o risco. A profundidade fica a um clique de distância, na aba Consultor.
A7: COMEÇAR O ATENDIMENTO
B8: 1 · CLIENTE | D8: As cinco perguntas e o resultado em linguagem simples. É a tela para virar o monitor para o cliente.
B9: 2 · COMPARAR | D9: As alternativas lado a lado e os gráficos de evolução, composição e renda.
B10: 3 · RELATÓRIO | D10: Resumo de uma página, pronto para imprimir ou salvar em PDF e entregar ao cliente.
A12: APROFUNDAR (MODO CONSULTOR)
B13: CONSULTOR | D13: Premissas, taxas, tributação, alertas e o painel técnico completo.
B14: MÊS A MÊS | D14: A projeção linha a linha: saldo, rendimento, aporte, custos e imposto.
B15: IMÓVEL | D15: Comprar para alugar: aluguel, vacância, IPTU, manutenção, compra e venda.
B16: PREVIDÊNCIA | D16: PGBL x VGBL, progressivo x regressivo e o valor real do benefício fiscal.
B17: ADERÊNCIA | D17: Como a planilha decide o que sugerir — e por que não é um ranking de rentabilidade.
A19: MANUTENÇÃO DA FERRAMENTA
B20: PRODUTOS | D20: Base de produtos: cadastrar, alterar taxa, ativar ou desativar.
B21: PREMISSAS | D21: Indicadores, cenários e todas as tabelas de tributação.
B22: FONTES | D22: De onde vem cada dado, com que atraso, e o registro de atualizações.
B23: GLOSSÁRIO | D23: Explicações curtas para usar na conversa com o cliente.
A25: SITUAÇÃO DOS DADOS AGORA
B26: Cenário em uso | E26: =CENARIO -> Base | G26: =IF(E29>0,"⚠ Há produtos com taxa de exemplo. Confira antes de usar com cliente.","Todos os produtos da base estão marcados como conferidos.") -> ⚠ Há produtos com taxa de exemplo. Confira antes de usar com cliente.
B27: Data de atualização dos dados | E27: =DATA_DADOS -> 2026-08-23
B28: Produtos ativos na base | E28: =COUNTIF(Produtos!$AD$9:$AD$78,"SIM") -> 24
B29: Produtos ainda não conferidos | E29: =COUNTIF(Produtos!$AB$9:$AB$78,"EXEMPLO*") -> 24
A31: ⚠ Ferramenta de apoio à conversa, de uso do profissional. Não é peça oficial de oferta e não substitui a lâmina, o regulamento, o prospecto do produto nem o questionário oficial de perfil (suitability).
A32: ⚠ Simulação baseada nas informações e premissas registradas nesta planilha. Os resultados reais podem ser diferentes. Rentabilidade passada não é garantia de rentabilidade futura e nenhum número aqui representa promessa de retorno.

Sheet Cliente
A1: SUA SIMULAÇÃO
A2: Poucas perguntas, e você vê o que pode acontecer com o seu dinheiro
A4: PASSO 1 · QUEM ESTAMOS ATENDENDO
B5: Nome do cliente | F5: (preencher)
B6: Data desta simulação | F6: =TODAY() -> 46257
A8: PASSO 2 · CINCO PERGUNTAS
A9: Só o que está em amarelo precisa ser preenchido. O resto a planilha calcula sozinha.
B10: Quanto você pretende investir agora? | F10: 150000
B11: Se ainda não tem certeza, use um valor aproximado — dá para mudar durante a conversa.
B12: Você pretende guardar mais alguma coisa por mês? | F12: 0
B13: Se não pretende, deixe zero.
B14: Por quanto tempo você pode deixar esse dinheiro investido? | F14: 5 a 10 anos
B15: Se escolheu “Prazo personalizado”, quantos meses? | F15: 120
B16: ➜ Prazo usado na simulação (meses) | F16: =IF(IN_HORIZONTE="Prazo personalizado",MAX(1,MIN(240,IN_PRAZO_CUSTOM)),IFERROR(INDEX(Premissas!$B$85:$B$90,MATCH(IN_HORIZONTE,Premissas!$A$85:$A$90,0)),120)) -> 120 | H16: ="Isso equivale a cerca de "&ROUND(IN_PRAZO/12,1)&" anos." -> Isso equivale a cerca de 10 anos.
B18: Você pode precisar desse dinheiro antes do prazo? | F18: Talvez
B19: Essa resposta pesa muito: ela define se vale a pena travar o dinheiro por uma taxa melhor.
B20: O que é mais importante para você? | F20: Equilíbrio entre segurança e rentabilidade
B21: Não existe resposta certa. Existe a resposta que combina com o seu momento.
B22: Perfil de investidor (do questionário oficial) | F22: Moderado
B23: Este campo repete o perfil já apurado no sistema da instituição. A planilha não substitui esse processo.
B24: =IF(IN_CAPITAL<=0,"⚠ Informe quanto o cliente pretende investir para a simulação começar.",IF(COUNTIF(Motor!$B$9:$G$9,1)=0,"⚠ Nenhuma alternativa escolhida ainda. Vá até a aba Consultor ou ligue a sugestão automática.","Tudo certo. Os resultados abaixo já refletem estas respostas.")) -> Tudo certo. Os resultados abaixo já refletem estas respostas.
A26: PASSO 3 · COMO SEU DINHEIRO PODE EVOLUIR
A27: Escolha uma alternativa para olhar de perto. A comparação completa está logo abaixo.
B28: Vamos olhar esta alternativa: | F28: A | H28: =IF(IN_DESTAQUE="Imóvel","Imóvel para aluguel",IFERROR(INDEX(Motor!$B$6:$G$6,MATCH("ALTERNATIVA "&IN_DESTAQUE,Motor!$B$5:$G$5,0)),"(não escolhida)")) -> Tesouro Prefixado 2031
B30: HOJE VOCÊ COLOCA | D30: ="EM "&ROUND(INT(IN_PRAZO/2)/12,0)&" ANOS" -> EM 5 ANOS | F30: ="EM "&ROUND(IN_PRAZO/12,0)&" ANOS" -> EM 10 ANOS | H30: GANHO ESTIMADO
B31: =IN_CAPITAL -> 150000 | D31: =IF(IN_DESTAQUE="Imóvel",MotorImovel!$B$35,IFERROR(INDEX(Motor!$B$41:$G$41,MATCH("ALTERNATIVA "&IN_DESTAQUE,Motor!$B$5:$G$5,0)),0)) -> 244983.51 | F31: =IF(IN_DESTAQUE="Imóvel",MotorImovel!$B$34,IFERROR(INDEX(Motor!$B$40:$G$40,MATCH("ALTERNATIVA "&IN_DESTAQUE,Motor!$B$5:$G$5,0)),0)) -> 410726.75 | H31: =IF(IN_DESTAQUE="Imóvel",MotorImovel!$B$38,IFERROR(INDEX(Motor!$B$44:$G$44,MATCH("ALTERNATIVA "&IN_DESTAQUE,Motor!$B$5:$G$5,0)),0)) -> 260726.75
B32: ="Mais "&TEXT(IN_APORTE,"R$ #,##0")&" por mês" -> Mais R$ 0 por mês | D32: ="Metade do caminho" -> Metade do caminho | F32: ="Já com imposto e custos descontados" -> Já com imposto e custos descontados | H32: ="Equivale a "&TEXT(IF(IN_DESTAQUE="Imóvel",MotorImovel!$B$41,IFERROR(INDEX(Motor!$B$47:$G$47,MATCH("ALTERNATIVA "&IN_DESTAQUE,Motor!$B$5:$G$5,0)),0)),"0.0%")&" sobre o investido" -> Equivale a 173.8% sobre o investido
A34: PASSO 4 · O QUE MAIS IMPORTA SABER SOBRE ESSA ALTERNATIVA
B35: PARA RETIRAR | D35: OSCILAÇÃO | F35: RENDA MENSAL POSSÍVEL | H35: IMPOSTO ESTIMADO | J35: ="O valor acima já está descontado de imposto e de custos. Em poder de compra de hoje, equivale a "&TEXT(IF(IN_DESTAQUE="Imóvel",MotorImovel!$B$36,IFERROR(INDEX(Motor!$B$42:$G$42,MATCH("ALTERNATIVA "&IN_DESTAQUE,Motor!$B$5:$G$5,0)),0)),"R$ #,##0")&"." -> O valor acima já está descontado de imposto e de custos. Em poder de compra de hoje, equivale a R$ 277,472.
B36: =IF(IN_DESTAQUE="Imóvel",MotorImovel!$B$50,IFERROR(INDEX(Motor!$B$56:$G$56,MATCH("ALTERNATIVA "&IN_DESTAQUE,Motor!$B$5:$G$5,0)),0)) -> Em 1 dia útil | D36: =IF(IN_DESTAQUE="Imóvel",MotorImovel!$B$51,IFERROR(INDEX(Motor!$B$57:$G$57,MATCH("ALTERNATIVA "&IN_DESTAQUE,Motor!$B$5:$G$5,0)),0)) -> Baixa | F36: =IF(IN_DESTAQUE="Imóvel",MotorImovel!$B$45,IFERROR(INDEX(Motor!$B$51:$G$51,MATCH("ALTERNATIVA "&IN_DESTAQUE,Motor!$B$5:$G$5,0)),0)) -> 3254.5196 | H36: =IF(IN_DESTAQUE="Imóvel",MotorImovel!$B$39,IFERROR(INDEX(Motor!$B$45:$G$45,MATCH("ALTERNATIVA "&IN_DESTAQUE,Motor!$B$5:$G$5,0)),0)) -> 46010.603
A38: PASSO 5 · OPÇÕES QUE PODEM FAZER SENTIDO PARA O SEU OBJETIVO
A39: Esta não é uma lista do que rende mais. É uma lista do que combina com o seu prazo, com a sua necessidade de retirar e com o que você disse ser mais importante. A escolha final é sua.
B40: Alternativa | C40: Você teria cerca de | D40: Ganho estimado | E40: Renda mensal possível | F40: Para retirar | G40: Oscilação | H40: Em R$ de hoje | I40: Aderência ao seu objetivo | J40: Ponto forte | K40: Ponto de atenção
B41: =IF(Motor!$B$9=0,"—",Motor!$B$6) -> Tesouro Prefixado 2031 | C41: =IF(Motor!$B$9=0,"",Motor!$B$40) -> 410726.75 | D41: =IF(Motor!$B$9=0,"",Motor!$B$44) -> 260726.75 | E41: =IF(Motor!$B$9=0,"",Motor!$B$51) -> 3254.5196 | F41: =IF(Motor!$B$9=0,"",Motor!$B$56) -> Em 1 dia útil | G41: =IF(Motor!$B$9=0,"",Motor!$B$57) -> Baixa | H41: =IF(Motor!$B$9=0,"",Motor!$B$42) -> 277472.27 | I41: =IF(Motor!$B$9=0,"",IFERROR(INDEX(Adequacao!$S$9:$S$78,MATCH(Motor!$B$6,Adequacao!$B$9:$B$78,0)),"—")) -> Pode fazer sentido | J41: =IF(Motor!$B$9=0,"",IFERROR(INDEX(Adequacao!$T$9:$T$78,MATCH(Motor!$B$6,Adequacao!$B$9:$B$78,0)),"")) -> A taxa fica travada na contratação: não cai se os juros da economia caírem. | K41: =IF(Motor!$B$9=0,"",IFERROR(INDEX(Adequacao!$U$9:$U$78,MATCH(Motor!$B$6,Adequacao!$B$9:$B$78,0)),"")) -> Se vender antes do vencimento, o preço pode estar abaixo do que você pagou.
B42: =IF(Motor!$C$9=0,"—",Motor!$C$6) -> Tesouro IPCA+ 2035 | C42: =IF(Motor!$C$9=0,"",Motor!$C$40) -> 353849.19 | D42: =IF(Motor!$C$9=0,"",Motor!$C$44) -> 203849.19 | E42: =IF(Motor!$C$9=0,"",Motor!$C$51) -> 2403.3348 | F42: =IF(Motor!$C$9=0,"",Motor!$C$56) -> Em 1 dia útil | G42: =IF(Motor!$C$9=0,"",Motor!$C$57) -> Baixa | H42: =IF(Motor!$C$9=0,"",Motor!$C$42) -> 239047.83 | I42: =IF(Motor!$C$9=0,"",IFERROR(INDEX(Adequacao!$S$9:$S$78,MATCH(Motor!$C$6,Adequacao!$B$9:$B$78,0)),"—")) -> Pode fazer sentido | J42: =IF(Motor!$C$9=0,"",IFERROR(INDEX(Adequacao!$T$9:$T$78,MATCH(Motor!$C$6,Adequacao!$B$9:$B$78,0)),"")) -> Protege o poder de compra: rende a inflação mais uma taxa fixa por cima. | K42: =IF(Motor!$C$9=0,"",IFERROR(INDEX(Adequacao!$U$9:$U$78,MATCH(Motor!$C$6,Adequacao!$B$9:$B$78,0)),"")) -> Se vender antes do vencimento, o preço pode estar abaixo do que você pagou.
B43: =IF(Motor!$D$9=0,"—",Motor!$D$6) -> Fundo CAIXA RF Crédito Privado LP | C43: =IF(Motor!$D$9=0,"",Motor!$D$40) -> 344477.27 | D43: =IF(Motor!$D$9=0,"",Motor!$D$44) -> 194477.27 | E43: =IF(Motor!$D$9=0,"",Motor!$D$51) -> 2387.9368 | F43: =IF(Motor!$D$9=0,"",Motor!$D$56) -> Em até 30 dias | G43: =IF(Motor!$D$9=0,"",Motor!$D$57) -> Baixa | H43: =IF(Motor!$D$9=0,"",Motor!$D$42) -> 232716.5 | I43: =IF(Motor!$D$9=0,"",IFERROR(INDEX(Adequacao!$S$9:$S$78,MATCH(Motor!$D$6,Adequacao!$B$9:$B$78,0)),"—")) -> Pode fazer sentido | J43: =IF(Motor!$D$9=0,"",IFERROR(INDEX(Adequacao!$T$9:$T$78,MATCH(Motor!$D$6,Adequacao!$B$9:$B$78,0)),"")) -> Combina com o prazo, a liquidez e a prioridade informados. | K43: =IF(Motor!$D$9=0,"",IFERROR(INDEX(Adequacao!$U$9:$U$78,MATCH(Motor!$D$6,Adequacao!$B$9:$B$78,0)),"")) -> Tem come-cotas em maio e novembro, que antecipam parte do imposto.
B44: =IF(Motor!$E$9=0,"—",Motor!$E$6) -> VGBL CAIXA Composto 30 — Regressivo | C44: =IF(Motor!$E$9=0,"",Motor!$E$40) -> 376188.27 | D44: =IF(Motor!$E$9=0,"",Motor!$E$44) -> 226188.27 | E44: =IF(Motor!$E$9=0,"",Motor!$E$51) -> 2730.3495 | F44: =IF(Motor!$E$9=0,"",Motor!$E$56) -> Em até 5 dias | G44: =IF(Motor!$E$9=0,"",Motor!$E$57) -> Média | H44: =IF(Motor!$E$9=0,"",Motor!$E$42) -> 254139.32 | I44: =IF(Motor!$E$9=0,"",IFERROR(INDEX(Adequacao!$S$9:$S$78,MATCH(Motor!$E$6,Adequacao!$B$9:$B$78,0)),"—")) -> Pode fazer sentido | J44: =IF(Motor!$E$9=0,"",IFERROR(INDEX(Adequacao!$T$9:$T$78,MATCH(Motor!$E$6,Adequacao!$B$9:$B$78,0)),"")) -> No prazo escolhido a previdência alcança a menor alíquota de imposto (10%). | K44: =IF(Motor!$E$9=0,"",IFERROR(INDEX(Adequacao!$U$9:$U$78,MATCH(Motor!$E$6,Adequacao!$B$9:$B$78,0)),"")) -> Não tem cobertura do FGC: quem responde pelo dinheiro é a seguradora.
B45: =IF(Motor!$F$9=0,"—",Motor!$F$6) -> PGBL CAIXA Composto 30 — Regressivo | C45: =IF(Motor!$F$9=0,"",Motor!$F$40) -> 353688.27 | D45: =IF(Motor!$F$9=0,"",Motor!$F$44) -> 203688.27 | E45: =IF(Motor!$F$9=0,"",Motor!$F$51) -> 2567.046 | F45: =IF(Motor!$F$9=0,"",Motor!$F$56) -> Em até 5 dias | G45: =IF(Motor!$F$9=0,"",Motor!$F$57) -> Média | H45: =IF(Motor!$F$9=0,"",Motor!$F$42) -> 238939.12 | I45: =IF(Motor!$F$9=0,"",IFERROR(INDEX(Adequacao!$S$9:$S$78,MATCH(Motor!$F$6,Adequacao!$B$9:$B$78,0)),"—")) -> Pode fazer sentido | J45: =IF(Motor!$F$9=0,"",IFERROR(INDEX(Adequacao!$T$9:$T$78,MATCH(Motor!$F$6,Adequacao!$B$9:$B$78,0)),"")) -> No prazo escolhido a previdência alcança a menor alíquota de imposto (10%). | K45: =IF(Motor!$F$9=0,"",IFERROR(INDEX(Adequacao!$U$9:$U$78,MATCH(Motor!$F$6,Adequacao!$B$9:$B$78,0)),"")) -> Não tem cobertura do FGC: quem responde pelo dinheiro é a seguradora.
B46: =IF(Motor!$G$9=0,"—",Motor!$G$6) -> Fundo CAIXA RF IPCA Longo Prazo | C46: =IF(Motor!$G$9=0,"",Motor!$G$40) -> 316495.51 | D46: =IF(Motor!$G$9=0,"",Motor!$G$44) -> 166495.51 | E46: =IF(Motor!$G$9=0,"",Motor!$G$51) -> 1970.2821 | F46: =IF(Motor!$G$9=0,"",Motor!$G$56) -> Em até 5 dias | G46: =IF(Motor!$G$9=0,"",Motor!$G$57) -> Média | H46: =IF(Motor!$G$9=0,"",Motor!$G$42) -> 213813.03 | I46: =IF(Motor!$G$9=0,"",IFERROR(INDEX(Adequacao!$S$9:$S$78,MATCH(Motor!$G$6,Adequacao!$B$9:$B$78,0)),"—")) -> Pode fazer sentido | J46: =IF(Motor!$G$9=0,"",IFERROR(INDEX(Adequacao!$T$9:$T$78,MATCH(Motor!$G$6,Adequacao!$B$9:$B$78,0)),"")) -> Protege o poder de compra: rende a inflação mais uma taxa fixa por cima. | K46: =IF(Motor!$G$9=0,"",IFERROR(INDEX(Adequacao!$U$9:$U$78,MATCH(Motor!$G$6,Adequacao!$B$9:$B$78,0)),"")) -> O valor oscila mês a mês: em prazo curto pode estar abaixo do que você aplicou.
B47: =IF(MotorImovel!$B$5=0,"—","Imóvel para aluguel") -> Imóvel para aluguel | C47: =IF(MotorImovel!$B$5=0,"",MotorImovel!$B$34) -> 329895.57 | D47: =IF(MotorImovel!$B$5=0,"",MotorImovel!$B$38) -> 174645.57 | E47: =IF(MotorImovel!$B$5=0,"",MotorImovel!$B$45) -> 827.86264 | F47: =IF(MotorImovel!$B$5=0,"",MotorImovel!$B$50) -> Depende de encontrar comprador — normalmente meses | G47: =IF(MotorImovel!$B$5=0,"",MotorImovel!$B$51) -> Média | H47: =IF(MotorImovel!$B$5=0,"",MotorImovel!$B$36) -> 222865.63 | I47: =IF(MotorImovel!$B$5=0,"",IFERROR(INDEX(Adequacao!$S$9:$S$78,MATCH("Imóvel para aluguel",Adequacao!$B$9:$B$78,0)),"—")) -> Pode fazer sentido | J47: =IF(MotorImovel!$B$5=0,"",IFERROR(INDEX(Adequacao!$T$9:$T$78,MATCH("Imóvel para aluguel",Adequacao!$B$9:$B$78,0)),"")) -> Combina com o prazo, a liquidez e a prioridade informados. | K47: =IF(MotorImovel!$B$5=0,"",IFERROR(INDEX(Adequacao!$U$9:$U$78,MATCH("Imóvel para aluguel",Adequacao!$B$9:$B$78,0)),"")) -> Não é dinheiro rápido: leva meses para virar caixa.
...

Sheet Comparar
A1: COMPARANDO AS ALTERNATIVAS
A2: As mesmas premissas, o mesmo prazo, o mesmo valor — para a comparação ser justa
A4: RESULTADO NO PRAZO ESCOLHIDO
A5: =" Cliente: "&IN_NOME&" · Valor: "&TEXT(IN_CAPITAL,"R$ #,##0")&" · Aporte mensal: "&TEXT(IN_APORTE,"R$ #,##0")&" · Prazo: "&IN_PRAZO&" meses · Cenário: "&CENARIO&" · Dados de "&DATA_DADOS -> Cliente: (preencher) · Valor: R$ 150,000 · Aporte mensal: R$ 0 · Prazo: 120 meses · Cenário: Base · Dados de 2026-08-23
B6: Alternativa | C6: Patrimônio líquido | D6: Total investido | E6: Ganho líquido | F6: Impostos | G6: Custos | H6: Em R$ de hoje | I6: Rent. acum. | J6: Taxa a.a. | K6: Ganho real a.a. | L6: Renda mensal | M6: Para retirar | N6: Oscilação | O6: Aderência ao objetivo | Q6: Auxiliar (só as em uso)
B7: =IF(Motor!$B$9=0,"— alternativa A não usada",Motor!$B$6) -> Tesouro Prefixado 2031 | C7: =IF(Motor!$B$9=0,0,Motor!$B$40) -> 410726.75 | D7: =IF(Motor!$B$9=0,0,Motor!$B$43) -> 150000 | E7: =IF(Motor!$B$9=0,0,Motor!$B$44) -> 260726.75 | F7: =IF(Motor!$B$9=0,0,Motor!$B$45) -> 46010.603 | G7: =IF(Motor!$B$9=0,0,Motor!$B$46) -> 5484.0377 | H7: =IF(Motor!$B$9=0,0,Motor!$B$42) -> 277472.27 | I7: =IF(Motor!$B$9=0,0,Motor!$B$47) -> 1.7381783 | J7: =IF(Motor!$B$9=0,0,Motor!$B$48) -> 0.1059772 | K7: =IF(Motor!$B$9=0,0,Motor!$B$49) -> 0.063439613 | L7: =IF(Motor!$B$9=0,0,Motor!$B$51) -> 3254.5196 | M7: =IF(Motor!$B$9=0,"",Motor!$B$56) -> Em 1 dia útil | N7: =IF(Motor!$B$9=0,"",Motor!$B$57) -> Baixa | O7: =IF(Motor!$B$9=0,"",IFERROR(INDEX(Adequacao!$S$9:$S$78,MATCH(Motor!$B$6,Adequacao!$B$9:$B$78,0)),"—")) -> Pode fazer sentido | Q7: =IF(Motor!$B$9=0,"",$C7) -> 410726.75
B8: =IF(Motor!$C$9=0,"— alternativa B não usada",Motor!$C$6) -> Tesouro IPCA+ 2035 | C8: =IF(Motor!$C$9=0,0,Motor!$C$40) -> 353849.19 | D8: =IF(Motor!$C$9=0,0,Motor!$C$43) -> 150000 | E8: =IF(Motor!$C$9=0,0,Motor!$C$44) -> 203849.19 | F8: =IF(Motor!$C$9=0,0,Motor!$C$45) -> 35973.386 | G8: =IF(Motor!$C$9=0,0,Motor!$C$46) -> 5002.2069 | H8: =IF(Motor!$C$9=0,0,Motor!$C$42) -> 239047.83 | I8: =IF(Motor!$C$9=0,0,Motor!$C$47) -> 1.3589946 | J8: =IF(Motor!$C$9=0,0,Motor!$C$48) -> 0.089614049 | K8: =IF(Motor!$C$9=0,0,Motor!$C$49) -> 0.047705816 | L8: =IF(Motor!$C$9=0,0,Motor!$C$51) -> 2403.3348 | M8: =IF(Motor!$C$9=0,"",Motor!$C$56) -> Em 1 dia útil | N8: =IF(Motor!$C$9=0,"",Motor!$C$57) -> Baixa | O8: =IF(Motor!$C$9=0,"",IFERROR(INDEX(Adequacao!$S$9:$S$78,MATCH(Motor!$C$6,Adequacao!$B$9:$B$78,0)),"—")) -> Pode fazer sentido | Q8: =IF(Motor!$C$9=0,"",$C8) -> 353849.19
B9: =IF(Motor!$D$9=0,"— alternativa C não usada",Motor!$D$6) -> Fundo CAIXA RF Crédito Privado LP | C9: =IF(Motor!$D$9=0,0,Motor!$D$40) -> 344477.27 | D9: =IF(Motor!$D$9=0,0,Motor!$D$43) -> 150000 | E9: =IF(Motor!$D$9=0,0,Motor!$D$44) -> 194477.27 | F9: =IF(Motor!$D$9=0,0,Motor!$D$45) -> 34319.518 | G9: =IF(Motor!$D$9=0,0,Motor!$D$46) -> 23378.968 | H9: =IF(Motor!$D$9=0,0,Motor!$D$42) -> 232716.5 | I9: =IF(Motor!$D$9=0,0,Motor!$D$47) -> 1.2965151 | J9: =IF(Motor!$D$9=0,0,Motor!$D$48) -> 0.086693154 | K9: =IF(Motor!$D$9=0,0,Motor!$D$49) -> 0.044897263 | L9: =IF(Motor!$D$9=0,0,Motor!$D$51) -> 2387.9368 | M9: =IF(Motor!$D$9=0,"",Motor!$D$56) -> Em até 30 dias | N9: =IF(Motor!$D$9=0,"",Motor!$D$57) -> Baixa | O9: =IF(Motor!$D$9=0,"",IFERROR(INDEX(Adequacao!$S$9:$S$78,MATCH(Motor!$D$6,Adequacao!$B$9:$B$78,0)),"—")) -> Pode fazer sentido | Q9: =IF(Motor!$D$9=0,"",$C9) -> 344477.27
B10: =IF(Motor!$E$9=0,"— alternativa D não usada",Motor!$E$6) -> VGBL CAIXA Composto 30 — Regressivo | C10: =IF(Motor!$E$9=0,0,Motor!$E$40) -> 376188.27 | D10: =IF(Motor!$E$9=0,0,Motor!$E$43) -> 150000 | E10: =IF(Motor!$E$9=0,0,Motor!$E$44) -> 226188.27 | F10: =IF(Motor!$E$9=0,0,Motor!$E$45) -> 39915.578 | G10: =IF(Motor!$E$9=0,0,Motor!$E$46) -> 38955.35 | H10: =IF(Motor!$E$9=0,0,Motor!$E$42) -> 254139.32 | I10: =IF(Motor!$E$9=0,0,Motor!$E$47) -> 1.5079218 | J10: =IF(Motor!$E$9=0,0,Motor!$E$48) -> 0.096305012 | K10: =IF(Motor!$E$9=0,0,Motor!$E$49) -> 0.054139434 | L10: =IF(Motor!$E$9=0,0,Motor!$E$51) -> 2730.3495 | M10: =IF(Motor!$E$9=0,"",Motor!$E$56) -> Em até 5 dias | N10: =IF(Motor!$E$9=0,"",Motor!$E$57) -> Média | O10: =IF(Motor!$E$9=0,"",IFERROR(INDEX(Adequacao!$S$9:$S$78,MATCH(Motor!$E$6,Adequacao!$B$9:$B$78,0)),"—")) -> Pode fazer sentido | Q10: =IF(Motor!$E$9=0,"",$C10) -> 376188.27
B11: =IF(Motor!$F$9=0,"— alternativa E não usada",Motor!$F$6) -> PGBL CAIXA Composto 30 — Regressivo | C11: =IF(Motor!$F$9=0,0,Motor!$F$40) -> 353688.27 | D11: =IF(Motor!$F$9=0,0,Motor!$F$43) -> 150000 | E11: =IF(Motor!$F$9=0,0,Motor!$F$44) -> 203688.27 | F11: =IF(Motor!$F$9=0,0,Motor!$F$45) -> 62415.578 | G11: =IF(Motor!$F$9=0,0,Motor!$F$46) -> 38955.35 | H11: =IF(Motor!$F$9=0,0,Motor!$F$42) -> 238939.12 | I11: =IF(Motor!$F$9=0,0,Motor!$F$47) -> 1.3579218 | J11: =IF(Motor!$F$9=0,0,Motor!$F$48) -> 0.089564489 | K11: =IF(Motor!$F$9=0,0,Motor!$F$49) -> 0.047658162 | L11: =IF(Motor!$F$9=0,0,Motor!$F$51) -> 2567.046 | M11: =IF(Motor!$F$9=0,"",Motor!$F$56) -> Em até 5 dias | N11: =IF(Motor!$F$9=0,"",Motor!$F$57) -> Média | O11: =IF(Motor!$F$9=0,"",IFERROR(INDEX(Adequacao!$S$9:$S$78,MATCH(Motor!$F$6,Adequacao!$B$9:$B$78,0)),"—")) -> Pode fazer sentido | Q11: =IF(Motor!$F$9=0,"",$C11) -> 353688.27
B12: =IF(Motor!$G$9=0,"— alternativa F não usada",Motor!$G$6) -> Fundo CAIXA RF IPCA Longo Prazo | C12: =IF(Motor!$G$9=0,0,Motor!$G$40) -> 316495.51 | D12: =IF(Motor!$G$9=0,0,Motor!$G$43) -> 150000 | E12: =IF(Motor!$G$9=0,0,Motor!$G$44) -> 166495.51 | F12: =IF(Motor!$G$9=0,0,Motor!$G$45) -> 29381.56 | G12: =IF(Motor!$G$9=0,0,Motor!$G$46) -> 22287.452 | H12: =IF(Motor!$G$9=0,0,Motor!$G$42) -> 213813.03 | I12: =IF(Motor!$G$9=0,0,Motor!$G$47) -> 1.1099701 | J12: =IF(Motor!$G$9=0,0,Motor!$G$48) -> 0.07752568 | K12: =IF(Motor!$G$9=0,0,Motor!$G$49) -> 0.036082385 | L12: =IF(Motor!$G$9=0,0,Motor!$G$51) -> 1970.2821 | M12: =IF(Motor!$G$9=0,"",Motor!$G$56) -> Em até 5 dias | N12: =IF(Motor!$G$9=0,"",Motor!$G$57) -> Média | O12: =IF(Motor!$G$9=0,"",IFERROR(INDEX(Adequacao!$S$9:$S$78,MATCH(Motor!$G$6,Adequacao!$B$9:$B$78,0)),"—")) -> Pode fazer sentido | Q12: =IF(Motor!$G$9=0,"",$C12) -> 316495.51
B13: =IF(MotorImovel!$B$5=0,"— alternativa imóvel não usada","Imóvel para aluguel") -> Imóvel para aluguel | C13: =IF(MotorImovel!$B$5=0,0,MotorImovel!$B$34) -> 329895.57 | D13: =IF(MotorImovel!$B$5=0,0,MotorImovel!$B$37) -> 155250 | E13: =IF(MotorImovel!$B$5=0,0,MotorImovel!$B$38) -> 174645.57 | F13: =IF(MotorImovel!$B$5=0,0,MotorImovel!$B$39) -> 16294.186 | G13: =IF(MotorImovel!$B$5=0,0,MotorImovel!$B$40) -> 68286.677 | H13: =IF(MotorImovel!$B$5=0,0,MotorImovel!$B$36) -> 222865.63 | I13: =IF(MotorImovel!$B$5=0,0,MotorImovel!$B$41) -> 1.1249312 | J13: =IF(MotorImovel!$B$5=0,0,MotorImovel!$B$42) -> 0.078287294 | K13: =IF(MotorImovel!$B$5=0,0,MotorImovel!$B$43) -> 0.036814706 | L13: =IF(MotorImovel!$B$5=0,0,MotorImovel!$B$45) -> 827.86264 | M13: =IF(MotorImovel!$B$5=0,"",MotorImovel!$B$50) -> Depende de encontrar comprador — normalmente meses | N13: =IF(MotorImovel!$B$5=0,"",MotorImovel!$B$51) -> Média | O13: =IF(MotorImovel!$B$5=0,"",IFERROR(INDEX(Adequacao!$S$9:$S$78,MATCH("Imóvel para aluguel",Adequacao!$B$9:$B$78,0)),"—")) -> Pode fazer sentido | Q13: =IF(MotorImovel!$B$5=0,"",$C13) -> 329895.57
A14: O maior patrimônio aparece destacado apenas como informação. Maior patrimônio não significa melhor escolha: liquidez, risco e objetivo pesam tanto quanto o número.
A15: EVOLUÇÃO ANO A ANO (base dos gráficos)
A16: Ano | B16: =IF(Motor!$B$9=0,"(não usada A)",Motor!$B$6) -> Tesouro Prefixado 2031 | C16: =IF(Motor!$C$9=0,"(não usada B)",Motor!$C$6) -> Tesouro IPCA+ 2035 | D16: =IF(Motor!$D$9=0,"(não usada C)",Motor!$D$6) -> Fundo CAIXA RF Crédito Privado LP | E16: =IF(Motor!$E$9=0,"(não usada D)",Motor!$E$6) -> VGBL CAIXA Composto 30 — Regressivo | F16: =IF(Motor!$F$9=0,"(não usada E)",Motor!$F$6) -> PGBL CAIXA Composto 30 — Regressivo | G16: =IF(Motor!$G$9=0,"(não usada F)",Motor!$G$6) -> Fundo CAIXA RF IPCA Longo Prazo | H16: =IF(MotorImovel!$B$5=0,"(não usada imóvel)","Imóvel para aluguel") -> Imóvel para aluguel
A17: 0 | B17: =IF(OR(0>IN_PRAZO,Motor!$B$9=0),"",INDEX(Motor!$R$61:$R$301,0+1)) -> 150000 | C17: =IF(OR(0>IN_PRAZO,Motor!$C$9=0),"",INDEX(Motor!$AG$61:$AG$301,0+1)) -> 150000 | D17: =IF(OR(0>IN_PRAZO,Motor!$D$9=0),"",INDEX(Motor!$AV$61:$AV$301,0+1)) -> 150000 | E17: =IF(OR(0>IN_PRAZO,Motor!$E$9=0),"",INDEX(Motor!$BK$61:$BK$301,0+1)) -> 150000 | F17: =IF(OR(0>IN_PRAZO,Motor!$F$9=0),"",INDEX(Motor!$BZ$61:$BZ$301,0+1)) -> 97500 | G17: =IF(OR(0>IN_PRAZO,Motor!$G$9=0),"",INDEX(Motor!$CO$61:$CO$301,0+1)) -> 150000 | H17: =IF(OR(0>IN_PRAZO,MotorImovel!$B$5=0),"",INDEX(MotorImovel!$W$55:$W$295,0+1)) -> 141000
A18: 1 | B18: =IF(OR(12>IN_PRAZO,Motor!$B$9=0),"",INDEX(Motor!$R$61:$R$301,12+1)) -> 164133.97 | C18: =IF(OR(12>IN_PRAZO,Motor!$C$9=0),"",INDEX(Motor!$AG$61:$AG$301,12+1)) -> 162025.8 | D18: =IF(OR(12>IN_PRAZO,Motor!$D$9=0),"",INDEX(Motor!$AV$61:$AV$301,12+1)) -> 162228.76 | E18: =IF(OR(12>IN_PRAZO,Motor!$E$9=0),"",INDEX(Motor!$BK$61:$BK$301,12+1)) -> 160473.12 | F18: =IF(OR(12>IN_PRAZO,Motor!$F$9=0),"",INDEX(Motor!$BZ$61:$BZ$301,12+1)) -> 107973.12 | G18: =IF(OR(12>IN_PRAZO,Motor!$G$9=0),"",INDEX(Motor!$CO$61:$CO$301,12+1)) -> 160936.56 | H18: =IF(OR(12>IN_PRAZO,MotorImovel!$B$5=0),"",INDEX(MotorImovel!$W$55:$W$295,12+1)) -> 153757.54
A19: 2 | B19: =IF(OR(24>IN_PRAZO,Motor!$B$9=0),"",INDEX(Motor!$R$61:$R$301,24+1)) -> 180868.07 | C19: =IF(OR(24>IN_PRAZO,Motor!$C$9=0),"",INDEX(Motor!$AG$61:$AG$301,24+1)) -> 176046.05 | D19: =IF(OR(24>IN_PRAZO,Motor!$D$9=0),"",INDEX(Motor!$AV$61:$AV$301,24+1)) -> 176326.97 | E19: =IF(OR(24>IN_PRAZO,Motor!$E$9=0),"",INDEX(Motor!$BK$61:$BK$301,24+1)) -> 172071.23 | F19: =IF(OR(24>IN_PRAZO,Motor!$F$9=0),"",INDEX(Motor!$BZ$61:$BZ$301,24+1)) -> 119571.23 | G19: =IF(OR(24>IN_PRAZO,Motor!$G$9=0),"",INDEX(Motor!$CO$61:$CO$301,24+1)) -> 173440.54 | H19: =IF(OR(24>IN_PRAZO,MotorImovel!$B$5=0),"",INDEX(MotorImovel!$W$55:$W$295,24+1)) -> 167675.08
A20: 3 | B20: =IF(OR(36>IN_PRAZO,Motor!$B$9=0),"",INDEX(Motor!$R$61:$R$301,36+1)) -> 200566.72 | C20: =IF(OR(36>IN_PRAZO,Motor!$C$9=0),"",INDEX(Motor!$AG$61:$AG$301,36+1)) -> 192302.04 | D20: =IF(OR(36>IN_PRAZO,Motor!$D$9=0),"",INDEX(Motor!$AV$61:$AV$301,36+1)) -> 192481.69 | E20: =IF(OR(36>IN_PRAZO,Motor!$E$9=0),"",INDEX(Motor!$BK$61:$BK$301,36+1)) -> 187600.96 | F20: =IF(OR(36>IN_PRAZO,Motor!$F$9=0),"",INDEX(Motor!$BZ$61:$BZ$301,36+1)) -> 142600.96 | G20: =IF(OR(36>IN_PRAZO,Motor!$G$9=0),"",INDEX(Motor!$CO$61:$CO$301,36+1)) -> 187653.15 | H20: =IF(OR(36>IN_PRAZO,MotorImovel!$B$5=0),"",INDEX(MotorImovel!$W$55:$W$295,36+1)) -> 182423.97
A21: 4 | B21: =IF(OR(48>IN_PRAZO,Motor!$B$9=0),"",INDEX(Motor!$R$61:$R$301,48+1)) -> 221539.97 | C21: =IF(OR(48>IN_PRAZO,Motor!$C$9=0),"",INDEX(Motor!$AG$61:$AG$301,48+1)) -> 209318.76 | D21: =IF(OR(48>IN_PRAZO,Motor!$D$9=0),"",INDEX(Motor!$AV$61:$AV$301,48+1)) -> 209170.09 | E21: =IF(OR(48>IN_PRAZO,Motor!$E$9=0),"",INDEX(Motor!$BK$61:$BK$301,48+1)) -> 202918.67 | F21: =IF(OR(48>IN_PRAZO,Motor!$F$9=0),"",INDEX(Motor!$BZ$61:$BZ$301,48+1)) -> 157918.67 | G21: =IF(OR(48>IN_PRAZO,Motor!$G$9=0),"",INDEX(Motor!$CO$61:$CO$301,48+1)) -> 202202.3 | H21: =IF(OR(48>IN_PRAZO,MotorImovel!$B$5=0),"",INDEX(MotorImovel!$W$55:$W$295,48+1)) -> 198096.35
A22: 5 | B22: =IF(OR(60>IN_PRAZO,Motor!$B$9=0),"",INDEX(Motor!$R$61:$R$301,60+1)) -> 244983.51 | C22: =IF(OR(60>IN_PRAZO,Motor!$C$9=0),"",INDEX(Motor!$AG$61:$AG$301,60+1)) -> 228040.8 | D22: =IF(OR(60>IN_PRAZO,Motor!$D$9=0),"",INDEX(Motor!$AV$61:$AV$301,60+1)) -> 227305.4 | E22: =IF(OR(60>IN_PRAZO,Motor!$E$9=0),"",INDEX(Motor!$BK$61:$BK$301,60+1)) -> 224873.32 | F22: =IF(OR(60>IN_PRAZO,Motor!$F$9=0),"",INDEX(Motor!$BZ$61:$BZ$301,60+1)) -> 187373.32 | G22: =IF(OR(60>IN_PRAZO,Motor!$G$9=0),"",INDEX(Motor!$CO$61:$CO$301,60+1)) -> 217879.48 | H22: =IF(OR(60>IN_PRAZO,MotorImovel!$B$5=0),"",INDEX(MotorImovel!$W$55:$W$295,60+1)) -> 215279.94
A23: 6 | B23: =IF(OR(72>IN_PRAZO,Motor!$B$9=0),"",INDEX(Motor!$R$61:$R$301,72+1)) -> 271188.3 | C23: =IF(OR(72>IN_PRAZO,Motor!$C$9=0),"",INDEX(Motor!$AG$61:$AG$301,72+1)) -> 248639.08 | D23: =IF(OR(72>IN_PRAZO,Motor!$D$9=0),"",INDEX(Motor!$AV$61:$AV$301,72+1)) -> 247013.06 | E23: =IF(OR(72>IN_PRAZO,Motor!$E$9=0),"",INDEX(Motor!$BK$61:$BK$301,72+1)) -> 245000.34 | F23: =IF(OR(72>IN_PRAZO,Motor!$F$9=0),"",INDEX(Motor!$BZ$61:$BZ$301,72+1)) -> 207500.34 | G23: =IF(OR(72>IN_PRAZO,Motor!$G$9=0),"",INDEX(Motor!$CO$61:$CO$301,72+1)) -> 234772.15 | H23: =IF(OR(72>IN_PRAZO,MotorImovel!$B$5=0),"",INDEX(MotorImovel!$W$55:$W$295,72+1)) -> 234129.65
A24: 7 | B24: =IF(OR(84>IN_PRAZO,Motor!$B$9=0),"",INDEX(Motor!$R$61:$R$301,84+1)) -> 300479.57 | C24: =IF(OR(84>IN_PRAZO,Motor!$C$9=0),"",INDEX(Motor!$AG$61:$AG$301,84+1)) -> 271301.61 | D24: =IF(OR(84>IN_PRAZO,Motor!$D$9=0),"",INDEX(Motor!$AV$61:$AV$301,84+1)) -> 268429.4 | E24: =IF(OR(84>IN_PRAZO,Motor!$E$9=0),"",INDEX(Motor!$BK$61:$BK$301,84+1)) -> 275108.62 | F24: =IF(OR(84>IN_PRAZO,Motor!$F$9=0),"",INDEX(Motor!$BZ$61:$BZ$301,84+1)) -> 245108.62 | G24: =IF(OR(84>IN_PRAZO,Motor!$G$9=0),"",INDEX(Motor!$CO$61:$CO$301,84+1)) -> 252974.55 | H24: =IF(OR(84>IN_PRAZO,MotorImovel!$B$5=0),"",INDEX(MotorImovel!$W$55:$W$295,84+1)) -> 254816.67
A25: 8 | B25: =IF(OR(96>IN_PRAZO,Motor!$B$9=0),"",INDEX(Motor!$R$61:$R$301,96+1)) -> 333220.85 | C25: =IF(OR(96>IN_PRAZO,Motor!$C$9=0),"",INDEX(Motor!$AG$61:$AG$301,96+1)) -> 296235.27 | D25: =IF(OR(96>IN_PRAZO,Motor!$D$9=0),"",INDEX(Motor!$AV$61:$AV$301,96+1)) -> 291702.56 | E25: =IF(OR(96>IN_PRAZO,Motor!$E$9=0),"",INDEX(Motor!$BK$61:$BK$301,96+1)) -> 301437.36 | F25: =IF(OR(96>IN_PRAZO,Motor!$F$9=0),"",INDEX(Motor!$BZ$61:$BZ$301,96+1)) -> 271437.36 | G25: =IF(OR(96>IN_PRAZO,Motor!$G$9=0),"",INDEX(Motor!$CO$61:$CO$301,96+1)) -> 272588.21 | H25: =IF(OR(96>IN_PRAZO,MotorImovel!$B$5=0),"",INDEX(MotorImovel!$W$55:$W$295,96+1)) -> 277530.23
A26: 9 | B26: =IF(OR(108>IN_PRAZO,Motor!$B$9=0),"",INDEX(Motor!$R$61:$R$301,108+1)) -> 369818.51 | C26: =IF(OR(108>IN_PRAZO,Motor!$C$9=0),"",INDEX(Motor!$AG$61:$AG$301,108+1)) -> 323667.66 | D26: =IF(OR(108>IN_PRAZO,Motor!$D$9=0),"",INDEX(Motor!$AV$61:$AV$301,108+1)) -> 316993.54 | E26: =IF(OR(108>IN_PRAZO,Motor!$E$9=0),"",INDEX(Motor!$BK$61:$BK$301,108+1)) -> 341881.39 | F26: =IF(OR(108>IN_PRAZO,Motor!$F$9=0),"",INDEX(Motor!$BZ$61:$BZ$301,108+1)) -> 319381.39 | G26: =IF(OR(108>IN_PRAZO,Motor!$G$9=0),"",INDEX(Motor!$CO$61:$CO$301,108+1)) -> 293722.56 | H26: =IF(OR(108>IN_PRAZO,MotorImovel!$B$5=0),"",INDEX(MotorImovel!$W$55:$W$295,108+1)) -> 302479.47
A27: 10 | B27: =IF(OR(120>IN_PRAZO,Motor!$B$9=0),"",INDEX(Motor!$R$61:$R$301,120+1)) -> 410726.75 | C27: =IF(OR(120>IN_PRAZO,Motor!$C$9=0),"",INDEX(Motor!$AG$61:$AG$301,120+1)) -> 353849.19 | D27: =IF(OR(120>IN_PRAZO,Motor!$D$9=0),"",INDEX(Motor!$AV$61:$AV$301,120+1)) -> 344477.27 | E27: =IF(OR(120>IN_PRAZO,Motor!$E$9=0),"",INDEX(Motor!$BK$61:$BK$301,120+1)) -> 376188.27 | F27: =IF(OR(120>IN_PRAZO,Motor!$F$9=0),"",INDEX(Motor!$BZ$61:$BZ$301,120+1)) -> 353688.27 | G27: =IF(OR(120>IN_PRAZO,Motor!$G$9=0),"",INDEX(Motor!$CO$61:$CO$301,120+1)) -> 316495.51 | H27: =IF(OR(120>IN_PRAZO,MotorImovel!$B$5=0),"",INDEX(MotorImovel!$W$55:$W$295,120+1)) -> 329895.57
A28: 11 | B28: =IF(OR(132>IN_PRAZO,Motor!$B$9=0),"",INDEX(Motor!$R$61:$R$301,132+1)) | C28: =IF(OR(132>IN_PRAZO,Motor!$C$9=0),"",INDEX(Motor!$AG$61:$AG$301,132+1)) | D28: =IF(OR(132>IN_PRAZO,Motor!$D$9=0),"",INDEX(Motor!$AV$61:$AV$301,132+1)) | E28: =IF(OR(132>IN_PRAZO,Motor!$E$9=0),"",INDEX(Motor!$BK$61:$BK$301,132+1)) | F28: =IF(OR(132>IN_PRAZO,Motor!$F$9=0),"",INDEX(Motor!$BZ$61:$BZ$301,132+1)) | G28: =IF(OR(132>IN_PRAZO,Motor!$G$9=0),"",INDEX(Motor!$CO$61:$CO$301,132+1)) | H28: =IF(OR(132>IN_PRAZO,MotorImovel!$B$5=0),"",INDEX(MotorImovel!$W$55:$W$295,132+1))
A29: 12 | B29: =IF(OR(144>IN_PRAZO,Motor!$B$9=0),"",INDEX(Motor!$R$61:$R$301,144+1)) | C29: =IF(OR(144>IN_PRAZO,Motor!$C$9=0),"",INDEX(Motor!$AG$61:$AG$301,144+1)) | D29: =IF(OR(144>IN_PRAZO,Motor!$D$9=0),"",INDEX(Motor!$AV$61:$AV$301,144+1)) | E29: =IF(OR(144>IN_PRAZO,Motor!$E$9=0),"",INDEX(Motor!$BK$61:$BK$301,144+1)) | F29: =IF(OR(144>IN_PRAZO,Motor!$F$9=0),"",INDEX(Motor!$BZ$61:$BZ$301,144+1)) | G29: =IF(OR(144>IN_PRAZO,Motor!$G$9=0),"",INDEX(Motor!$CO$61:$CO$301,144+1)) | H29: =IF(OR(144>IN_PRAZO,MotorImovel!$B$5=0),"",INDEX(MotorImovel!$W$55:$W$295,144+1))
A30: 13 | B30: =IF(OR(156>IN_PRAZO,Motor!$B$9=0),"",INDEX(Motor!$R$61:$R$301,156+1)) | C30: =IF(OR(156>IN_PRAZO,Motor!$C$9=0),"",INDEX(Motor!$AG$61:$AG$301,156+1)) | D30: =IF(OR(156>IN_PRAZO,Motor!$D$9=0),"",INDEX(Motor!$AV$61:$AV$301,156+1)) | E30: =IF(OR(156>IN_PRAZO,Motor!$E$9=0),"",INDEX(Motor!$BK$61:$BK$301,156+1)) | F30: =IF(OR(156>IN_PRAZO,Motor!$F$9=0),"",INDEX(Motor!$BZ$61:$BZ$301,156+1)) | G30: =IF(OR(156>IN_PRAZO,Motor!$G$9=0),"",INDEX(Motor!$CO$61:$CO$301,156+1)) | H30: =IF(OR(156>IN_PRAZO,MotorImovel!$B$5=0),"",INDEX(MotorImovel!$W$55:$W$295,156+1))
A31: 14 | B31: =IF(OR(168>IN_PRAZO,Motor!$B$9=0),"",INDEX(Motor!$R$61:$R$301,168+1)) | C31: =IF(OR(168>IN_PRAZO,Motor!$C$9=0),"",INDEX(Motor!$AG$61:$AG$301,168+1)) | D31: =IF(OR(168>IN_PRAZO,Motor!$D$9=0),"",INDEX(Motor!$AV$61:$AV$301,168+1)) | E31: =IF(OR(168>IN_PRAZO,Motor!$E$9=0),"",INDEX(Motor!$BK$61:$BK$301,168+1)) | F31: =IF(OR(168>IN_PRAZO,Motor!$F$9=0),"",INDEX(Motor!$BZ$61:$BZ$301,168+1)) | G31: =IF(OR(168>IN_PRAZO,Motor!$G$9=0),"",INDEX(Motor!$CO$61:$CO$301,168+1)) | H31: =IF(OR(168>IN_PRAZO,MotorImovel!$B$5=0),"",INDEX(MotorImovel!$W$55:$W$295,168+1))
A32: 15 | B32: =IF(OR(180>IN_PRAZO,Motor!$B$9=0),"",INDEX(Motor!$R$61:$R$301,180+1)) | C32: =IF(OR(180>IN_PRAZO,Motor!$C$9=0),"",INDEX(Motor!$AG$61:$AG$301,180+1)) | D32: =IF(OR(180>IN_PRAZO,Motor!$D$9=0),"",INDEX(Motor!$AV$61:$AV$301,180+1)) | E32: =IF(OR(180>IN_PRAZO,Motor!$E$9=0),"",INDEX(Motor!$BK$61:$BK$301,180+1)) | F32: =IF(OR(180>IN_PRAZO,Motor!$F$9=0),"",INDEX(Motor!$BZ$61:$BZ$301,180+1)) | G32: =IF(OR(180>IN_PRAZO,Motor!$G$9=0),"",INDEX(Motor!$CO$61:$CO$301,180+1)) | H32: =IF(OR(180>IN_PRAZO,MotorImovel!$B$5=0),"",INDEX(MotorImovel!$W$55:$W$295,180+1))
A33: 16 | B33: =IF(OR(192>IN_PRAZO,Motor!$B$9=0),"",INDEX(Motor!$R$61:$R$301,192+1)) | C33: =IF(OR(192>IN_PRAZO,Motor!$C$9=0),"",INDEX(Motor!$AG$61:$AG$301,192+1)) | D33: =IF(OR(192>IN_PRAZO,Motor!$D$9=0),"",INDEX(Motor!$AV$61:$AV$301,192+1)) | E33: =IF(OR(192>IN_PRAZO,Motor!$E$9=0),"",INDEX(Motor!$BK$61:$BK$301,192+1)) | F33: =IF(OR(192>IN_PRAZO,Motor!$F$9=0),"",INDEX(Motor!$BZ$61:$BZ$301,192+1)) | G33: =IF(OR(192>IN_PRAZO,Motor!$G$9=0),"",INDEX(Motor!$CO$61:$CO$301,192+1)) | H33: =IF(OR(192>IN_PRAZO,MotorImovel!$B$5=0),"",INDEX(MotorImovel!$W$55:$W$295,192+1))
A34: 17 | B34: =IF(OR(204>IN_PRAZO,Motor!$B$9=0),"",INDEX(Motor!$R$61:$R$301,204+1)) | C34: =IF(OR(204>IN_PRAZO,Motor!$C$9=0),"",INDEX(Motor!$AG$61:$AG$301,204+1)) | D34: =IF(OR(204>IN_PRAZO,Motor!$D$9=0),"",INDEX(Motor!$AV$61:$AV$301,204+1)) | E34: =IF(OR(204>IN_PRAZO,Motor!$E$9=0),"",INDEX(Motor!$BK$61:$BK$301,204+1)) | F34: =IF(OR(204>IN_PRAZO,Motor!$F$9=0),"",INDEX(Motor!$BZ$61:$BZ$301,204+1)) | G34: =IF(OR(204>IN_PRAZO,Motor!$G$9=0),"",INDEX(Motor!$CO$61:$CO$301,204+1)) | H34: =IF(OR(204>IN_PRAZO,MotorImovel!$B$5=0),"",INDEX(MotorImovel!$W$55:$W$295,204+1))
A35: 18 | B35: =IF(OR(216>IN_PRAZO,Motor!$B$9=0),"",INDEX(Motor!$R$61:$R$301,216+1)) | C35: =IF(OR(216>IN_PRAZO,Motor!$C$9=0),"",INDEX(Motor!$AG$61:$AG$301,216+1)) | D35: =IF(OR(216>IN_PRAZO,Motor!$D$9=0),"",INDEX(Motor!$AV$61:$AV$301,216+1)) | E35: =IF(OR(216>IN_PRAZO,Motor!$E$9=0),"",INDEX(Motor!$BK$61:$BK$301,216+1)) | F35: =IF(OR(216>IN_PRAZO,Motor!$F$9=0),"",INDEX(Motor!$BZ$61:$BZ$301,216+1)) | G35: =IF(OR(216>IN_PRAZO,Motor!$G$9=0),"",INDEX(Motor!$CO$61:$CO$301,216+1)) | H35: =IF(OR(216>IN_PRAZO,MotorImovel!$B$5=0),"",INDEX(MotorImovel!$W$55:$W$295,216+1))
A36: 19 | B36: =IF(OR(228>IN_PRAZO,Motor!$B$9=0),"",INDEX(Motor!$R$61:$R$301,228+1)) | C36: =IF(OR(228>IN_PRAZO,Motor!$C$9=0),"",INDEX(Motor!$AG$61:$AG$301,228+1)) | D36: =IF(OR(228>IN_PRAZO,Motor!$D$9=0),"",INDEX(Motor!$AV$61:$AV$301,228+1)) | E36: =IF(OR(228>IN_PRAZO,Motor!$E$9=0),"",INDEX(Motor!$BK$61:$BK$301,228+1)) | F36: =IF(OR(228>IN_PRAZO,Motor!$F$9=0),"",INDEX(Motor!$BZ$61:$BZ$301,228+1)) | G36: =IF(OR(228>IN_PRAZO,Motor!$G$9=0),"",INDEX(Motor!$CO$61:$CO$301,228+1)) | H36: =IF(OR(228>IN_PRAZO,MotorImovel!$B$5=0),"",INDEX(MotorImovel!$W$55:$W$295,228+1))
A37: 20 | B37: =IF(OR(240>IN_PRAZO,Motor!$B$9=0),"",INDEX(Motor!$R$61:$R$301,240+1)) | C37: =IF(OR(240>IN_PRAZO,Motor!$C$9=0),"",INDEX(Motor!$AG$61:$AG$301,240+1)) | D37: =IF(OR(240>IN_PRAZO,Motor!$D$9=0),"",INDEX(Motor!$AV$61:$AV$301,240+1)) | E37: =IF(OR(240>IN_PRAZO,Motor!$E$9=0),"",INDEX(Motor!$BK$61:$BK$301,240+1)) | F37: =IF(OR(240>IN_PRAZO,Motor!$F$9=0),"",INDEX(Motor!$BZ$61:$BZ$301,240+1)) | G37: =IF(OR(240>IN_PRAZO,Motor!$G$9=0),"",INDEX(Motor!$CO$61:$CO$301,240+1)) | H37: =IF(OR(240>IN_PRAZO,MotorImovel!$B$5=0),"",INDEX(MotorImovel!$W$55:$W$295,240+1))
A92: ⚠ Simulação baseada nas informações e premissas registradas nesta planilha. Os resultados reais podem ser diferentes. Rentabilidade passada não é garantia de rentabilidade futura e nenhum número aqui representa promessa de retorno.
B94: ◀ INÍCIO | D94: ◀ CLIENTE | F94: MÊS A MÊS | H94: VER DETALHES | J94: GERAR RELATÓRIO

Sheet Consultor
A1: MODO CONSULTOR
A2: Premissas, taxas, tributação e a origem de cada número
A4: PARÂMETROS DA SIMULAÇÃO
B5: Cenário de premissas | D5: Base | E5: Cenário não é promessa. É um conjunto de premissas escolhido por você.
B6: Data de início da simulação | D6: =TODAY() -> 46257 | E6: Define o mês do come-cotas e as datas de carência.
B7: Corrigir o aporte mensal pela inflação? | D7: Não | E7: Se Sim, o aporte cresce junto com o IPCA do cenário.
B8: Preencher as alternativas com a sugestão automática? | D8: Sim | E8: Se Sim, os seis lugares usam a ordem de aderência da aba Adequação.
B9: Reinvestir a restituição do PGBL? | D9: Sim | E9: Se Sim, o benefício fiscal volta como aporte extra em maio de cada ano.
B10: Renda bruta anual tributável do cliente | D10: 0 | E10: Base do limite de 12% de dedução do PGBL.
B11: Alíquota marginal do IRPF do cliente | D11: 0.275 | E11: Quanto o cliente deixa de pagar sobre cada real deduzido.
B12: O cliente declara IR no modelo completo? | D12: Não | E12: Sem isso, o PGBL perde a razão de existir e o VGBL costuma ser o caminho.
B13: ➜ Benefício fiscal anual do PGBL | D13: =IF(PGBL_COMPLETA<>"Sim",0,MIN(IN_APORTE*12,PGBL_RENDA*LIMITE_PGBL)*PGBL_ALIQ) -> 0 | E13: =IF(PGBL_COMPLETA<>"Sim","O cliente não declara no modelo completo: o PGBL não gera benefício e o VGBL tende a ser o caminho.","Valor recorrente por ano. No primeiro ano o aporte inicial também é dedutível, gerando um benefício adicional de "&TEXT(MIN(IN_CAPITAL,MAX(0,PGBL_RENDA*LIMITE_PGBL-IN_APORTE*12))*PGBL_ALIQ,"R$ #,##0")&".") -> O cliente não declara no modelo completo: o PGBL não gera benefício e o VGBL tende a ser o caminho.
A15: ALTERNATIVAS EM COMPARAÇÃO
B16: Lugar | C16: Escolha manual | D16: Aderência da escolha | E16: Sugestão automática | G16: Nota | H16: EM USO NA SIMULAÇÃO
B17: A | D17: =IFERROR(IF($C17="","",INDEX(Adequacao!$S$9:$S$78,MATCH($C17,Adequacao!$B$9:$B$78,0))),"") | E17: =Adequacao!$B$82 -> Tesouro Prefixado 2031 | G17: =Adequacao!$C$82 -> 96.3 | H17: =IF(AUTO_SUGESTAO="Sim",Adequacao!$B$82,$C17) -> Tesouro Prefixado 2031 | J17: =IF(AUTO_SUGESTAO="Sim","A sugestão automática está LIGADA: a coluna EM USO segue a ordem de aderência. Para escolher à mão, mude o parâmetro para Não e preencha a coluna Escolha manual.","A sugestão automática está DESLIGADA: vale o que você escolher na coluna Escolha manual. A coluna Sugestão automática continua visível só para comparação.") -> A sugestão automática está LIGADA: a coluna EM USO segue a ordem de aderência. Para escolher à mão, mude o parâmetro para Não e preencha a coluna Escolha manual.
B18: B | D18: =IFERROR(IF($C18="","",INDEX(Adequacao!$S$9:$S$78,MATCH($C18,Adequacao!$B$9:$B$78,0))),"") | E18: =Adequacao!$B$83 -> Tesouro IPCA+ 2035 | G18: =Adequacao!$C$83 -> 96.3 | H18: =IF(AUTO_SUGESTAO="Sim",Adequacao!$B$83,$C18) -> Tesouro IPCA+ 2035
B19: C | D19: =IFERROR(IF($C19="","",INDEX(Adequacao!$S$9:$S$78,MATCH($C19,Adequacao!$B$9:$B$78,0))),"") | E19: =Adequacao!$B$84 -> Fundo CAIXA RF Crédito Privado LP | G19: =Adequacao!$C$84 -> 94 | H19: =IF(AUTO_SUGESTAO="Sim",Adequacao!$B$84,$C19) -> Fundo CAIXA RF Crédito Privado LP
B20: D | D20: =IFERROR(IF($C20="","",INDEX(Adequacao!$S$9:$S$78,MATCH($C20,Adequacao!$B$9:$B$78,0))),"") | E20: =Adequacao!$B$85 -> VGBL CAIXA Composto 30 — Regressivo | G20: =Adequacao!$C$85 -> 91.3 | H20: =IF(AUTO_SUGESTAO="Sim",Adequacao!$B$85,$C20) -> VGBL CAIXA Composto 30 — Regressivo
B21: E | D21: =IFERROR(IF($C21="","",INDEX(Adequacao!$S$9:$S$78,MATCH($C21,Adequacao!$B$9:$B$78,0))),"") | E21: =Adequacao!$B$86 -> PGBL CAIXA Composto 30 — Regressivo | G21: =Adequacao!$C$86 -> 91.3 | H21: =IF(AUTO_SUGESTAO="Sim",Adequacao!$B$86,$C21) -> PGBL CAIXA Composto 30 — Regressivo
B22: F | D22: =IFERROR(IF($C22="","",INDEX(Adequacao!$S$9:$S$78,MATCH($C22,Adequacao!$B$9:$B$78,0))),"") | E22: =Adequacao!$B$87 -> Fundo CAIXA RF IPCA Longo Prazo | G22: =Adequacao!$C$87 -> 90.5 | H22: =IF(AUTO_SUGESTAO="Sim",Adequacao!$B$87,$C22) -> Fundo CAIXA RF IPCA Longo Prazo
A24: PAINEL TÉCNICO — DE ONDE VEM CADA NÚMERO
B25: Parâmetro | D25: =IF(Motor!$B$9=0,"(A) não usada",Motor!$B$6) -> Tesouro Prefixado 2031 | E25: =IF(Motor!$C$9=0,"(B) não usada",Motor!$C$6) -> Tesouro IPCA+ 2035 | F25: =IF(Motor!$D$9=0,"(C) não usada",Motor!$D$6) -> Fundo CAIXA RF Crédito Privado LP | G25: =IF(Motor!$E$9=0,"(D) não usada",Motor!$E$6) -> VGBL CAIXA Composto 30 — Regressivo | H25: =IF(Motor!$F$9=0,"(E) não usada",Motor!$F$6) -> PGBL CAIXA Composto 30 — Regressivo | I25: =IF(Motor!$G$9=0,"(F) não usada",Motor!$G$6) -> Fundo CAIXA RF IPCA Longo Prazo | J25: =IF(MotorImovel!$B$5=0,"(imóvel fora)","Imóvel para aluguel") -> Imóvel para aluguel
B26: Produto | D26: =Motor!$B$6 -> Tesouro Prefixado 2031 | E26: =Motor!$C$6 -> Tesouro IPCA+ 2035 | F26: =Motor!$D$6 -> Fundo CAIXA RF Crédito Privado LP | G26: =Motor!$E$6 -> VGBL CAIXA Composto 30 — Regressivo | H26: =Motor!$F$6 -> PGBL CAIXA Composto 30 — Regressivo | I26: =Motor!$G$6 -> Fundo CAIXA RF IPCA Longo Prazo | J26: ="Imóvel para aluguel" -> Imóvel para aluguel
B27: Categoria | D27: =Motor!$B$10 -> Renda Fixa | E27: =Motor!$C$10 -> Renda Fixa | F27: =Motor!$D$10 -> Fundo | G27: =Motor!$E$10 -> Previdência | H27: =Motor!$F$10 -> Previdência | I27: =Motor!$G$10 -> Fundo | J27: ="Imobiliário" -> Imobiliário
B28: Emissor / gestor | D28: =Motor!$B$11 -> Tesouro Nacional | E28: =Motor!$C$11 -> Tesouro Nacional | F28: =Motor!$D$11 -> CAIXA Asset | G28: =Motor!$E$11 -> CAIXA Vida e Previdência | H28: =Motor!$F$11 -> CAIXA Vida e Previdência | I28: =Motor!$G$11 -> CAIXA Asset | J28: ="Mercado" -> Mercado
B29: Indexador | D29: =Motor!$B$12 -> PRE | E29: =Motor!$C$12 -> IPCA | F29: =Motor!$D$12 -> CDI | G29: =Motor!$E$12 -> CDI | H29: =Motor!$F$12 -> CDI | I29: =Motor!$G$12 -> IPCA | J29: ="Valorização + aluguel" -> Valorização + aluguel
B30: % do indexador | D30: =Motor!$B$13 -> 1 | E30: =Motor!$C$13 -> 1 | F30: =Motor!$D$13 -> 1.04 | G30: =Motor!$E$13 -> 1 | H30: =Motor!$F$13 -> 1 | I30: =Motor!$G$13 -> 1 | J30: =1 -> 1
B31: Spread contratado a.a. | D31: =Motor!$B$14 -> 0.12 | E31: =Motor!$C$14 -> 0.06 | F31: =Motor!$D$14 -> 0 | G31: =Motor!$E$14 -> 0.015 | H31: =Motor!$F$14 -> 0.015 | I31: =Motor!$G$14 -> 0.06 | J31: =MotorImovel!$B$20 -> 0.04
B32: Retorno BRUTO a.a. no cenário | D32: =Motor!$B$17 -> 0.12 | E32: =Motor!$C$17 -> 0.1024 | F32: =Motor!$D$17 -> 0.11336 | G32: =Motor!$E$17 -> 0.124 | H32: =Motor!$F$17 -> 0.124 | I32: =Motor!$G$17 -> 0.1024 | J32: =MotorImovel!$B$20 -> 0.04
B33: Taxa de administração a.a. | D33: =Motor!$B$20 -> 0 | E33: =Motor!$C$20 -> 0 | F33: =Motor!$D$20 -> 0.01 | G33: =Motor!$E$20 -> 0.015 | H33: =Motor!$F$20 -> 0.015 | I33: =Motor!$G$20 -> 0.01 | J33: =MotorImovel!$B$19 -> 0.08
B34: Custódia a.a. | D34: =Motor!$B$21 -> 0.002 | E34: =Motor!$C$21 -> 0.002 | F34: =Motor!$D$21 -> 0 | G34: =Motor!$E$21 -> 0 | H34: =Motor!$F$21 -> 0 | I34: =Motor!$G$21 -> 0 | J34: =MotorImovel!$B$17 -> 0.006
B35: Taxa de performance | D35: =Motor!$B$23 -> 0 | E35: =Motor!$C$23 -> 0 | F35: =Motor!$D$23 -> 0 | G35: =Motor!$E$23 -> 0 | H35: =Motor!$F$23 -> 0 | I35: =Motor!$G$23 -> 0 | J35: =0 -> 0
B36: Carregamento entrada / saída | D36: =TEXT(Motor!$B$24,"0.00%")&" / "&TEXT(Motor!$B$25,"0.00%") -> 0.00% / 0.00% | E36: =TEXT(Motor!$C$24,"0.00%")&" / "&TEXT(Motor!$C$25,"0.00%") -> 0.00% / 0.00% | F36: =TEXT(Motor!$D$24,"0.00%")&" / "&TEXT(Motor!$D$25,"0.00%") -> 0.00% / 0.00% | G36: =TEXT(Motor!$E$24,"0.00%")&" / "&TEXT(Motor!$E$25,"0.00%") -> 0.00% / 0.00% | H36: =TEXT(Motor!$F$24,"0.00%")&" / "&TEXT(Motor!$F$25,"0.00%") -> 0.00% / 0.00% | I36: =TEXT(Motor!$G$24,"0.00%")&" / "&TEXT(Motor!$G$25,"0.00%") -> 0.00% / 0.00% | J36: ="—" -> —
B37: Retorno LÍQUIDO a.a. estimado | D37: =Motor!$B$36 -> 0.11778307 | E37: =Motor!$C$36 -> 0.10021503 | F37: =Motor!$D$36 -> 0.10237557 | G37: =Motor!$E$36 -> 0.10741665 | H37: =Motor!$F$36 -> 0.10741665 | I37: =Motor!$G$36 -> 0.091514773 | J37: =MotorImovel!$B$42 -> 0.078287294
B38: Regime tributário | D38: =Motor!$B$8 -> RF_REGR | E38: =Motor!$C$8 -> RF_REGR | F38: =Motor!$D$8 -> FUNDO_LP | G38: =Motor!$E$8 -> PREV_REGR | H38: =Motor!$F$8 -> PREV_REGR | I38: =Motor!$G$8 -> FUNDO_LP | J38: ="Carnê-leão + ganho de capital" -> Carnê-leão + ganho de capital
B39: Come-cotas | D39: =Motor!$B$27 -> 0 | E39: =Motor!$C$27 -> 0 | F39: =Motor!$D$27 -> 1 | G39: =Motor!$E$27 -> 0 | H39: =Motor!$F$27 -> 0 | I39: =Motor!$G$27 -> 1 | J39: =0 -> 0
B40: Carência (dias) | D40: =Motor!$B$29 -> 0 | E40: =Motor!$C$29 -> 0 | F40: =Motor!$D$29 -> 0 | G40: =Motor!$E$29 -> 0 | H40: =Motor!$F$29 -> 0 | I40: =Motor!$G$29 -> 0 | J40: ="—" -> —
B41: Liquidez após carência (dias) | D41: =Motor!$B$30 -> 1 | E41: =Motor!$C$30 -> 1 | F41: =Motor!$D$30 -> 30 | G41: =Motor!$E$30 -> 5 | H41: =Motor!$F$30 -> 5 | I41: =Motor!$G$30 -> 5 | J41: ="meses" -> meses
B42: Aplicação mínima | D42: =Motor!$B$31 -> 100 | E42: =Motor!$C$31 -> 100 | F42: =Motor!$D$31 -> 5000 | G42: =Motor!$E$31 -> 5000 | H42: =Motor!$F$31 -> 5000 | I42: =Motor!$G$31 -> 5000 | J42: =MotorImovel!$B$10 -> 155250
B43: Risco (1-5) | D43: =Motor!$B$32 -> 2 | E43: =Motor!$C$32 -> 2 | F43: =Motor!$D$32 -> 2 | G43: =Motor!$E$32 -> 3 | H43: =Motor!$F$32 -> 3 | I43: =Motor!$G$32 -> 3 | J43: =3 -> 3
...

Sheet MesAMes
A1: PROJEÇÃO MÊS A MÊS
A2: Cada linha mostra exatamente de onde veio cada número
B4: Alternativa em exibição | D4: A | E4: =IFERROR(INDEX(Motor!$B$6:$G$6,$D$5),"(não escolhida)") -> Tesouro Prefixado 2031 | I4: ◀ INÍCIO | J4: ◀ CLIENTE | K4: COMPARAR
B5: (número do lugar escolhido — calculado) | D5: =IFERROR(MATCH("ALTERNATIVA "&MES_DETALHE,Motor!$B$5:$G$5,0),1) -> 1 | E5: ="O imóvel tem mecânica própria e é detalhado na aba MotorImovel, a partir da aba Imóvel." -> O imóvel tem mecânica própria e é detalhado na aba MotorImovel, a partir da aba Imóvel.
A6: As linhas depois do prazo escolhido aparecem esmaecidas: elas mostram o que aconteceria se o cliente deixasse o dinheiro por mais tempo.
A8: Mês | B8: Data | C8: Saldo inicial | D8: Rendimento bruto | E8: Aporte | F8: Custos | G8: Imposto no mês | H8: Saldo final | I8: IR se resgatar agora | J8: Valor líquido no resgate | K8: Valor líquido em R$ de hoje | M8: Legenda
A9: 0 | B9: =EDATE(DATA_INICIO,$A9) -> 46257 | C9: =IFERROR(INDEX(Motor!$F$61:$CP$301,$A9+1,($D$5-1)*15+1),0) -> 0 | D9: =IFERROR(INDEX(Motor!$F$61:$CP$301,$A9+1,($D$5-1)*15+4),0) -> 0 | E9: =IFERROR(INDEX(Motor!$F$61:$CP$301,$A9+1,($D$5-1)*15+2),0) -> 150000 | F9: =IFERROR(INDEX(Motor!$F$61:$CP$301,$A9+1,($D$5-1)*15+3)+INDEX(Motor!$F$61:$CP$301,$A9+1,($D$5-1)*15+5)+INDEX(Motor!$F$61:$CP$301,$A9+1,($D$5-1)*15+6),0) -> 0 | G9: =IFERROR(INDEX(Motor!$F$61:$CP$301,$A9+1,($D$5-1)*15+7),0) -> 0 | H9: =IFERROR(INDEX(Motor!$F$61:$CP$301,$A9+1,($D$5-1)*15+8),0) -> 150000 | I9: =IFERROR(INDEX(Motor!$F$61:$CP$301,$A9+1,($D$5-1)*15+12),0) -> 0 | J9: =IFERROR(INDEX(Motor!$F$61:$CP$301,$A9+1,($D$5-1)*15+13),0) -> 150000 | K9: =IFERROR(INDEX(Motor!$F$61:$CP$301,$A9+1,($D$5-1)*15+14),0) -> 150000 | M9: Linha verde: o mês do prazo escolhido pelo cliente.
A10: 1 | B10: =EDATE(DATA_INICIO,$A10) -> 46288 | C10: =IFERROR(INDEX(Motor!$F$61:$CP$301,$A10+1,($D$5-1)*15+1),0) -> 150000 | D10: =IFERROR(INDEX(Motor!$F$61:$CP$301,$A10+1,($D$5-1)*15+4),0) -> 1423.3189 | E10: =IFERROR(INDEX(Motor!$F$61:$CP$301,$A10+1,($D$5-1)*15+2),0) -> 0 | F10: =IFERROR(INDEX(Motor!$F$61:$CP$301,$A10+1,($D$5-1)*15+3)+INDEX(Motor!$F$61:$CP$301,$A10+1,($D$5-1)*15+5)+INDEX(Motor!$F$61:$CP$301,$A10+1,($D$5-1)*15+6),0) -> 25 | G10: =IFERROR(INDEX(Motor!$F$61:$CP$301,$A10+1,($D$5-1)*15+7),0) -> 0 | H10: =IFERROR(INDEX(Motor!$F$61:$CP$301,$A10+1,($D$5-1)*15+8),0) -> 151398.32 | I10: =IFERROR(INDEX(Motor!$F$61:$CP$301,$A10+1,($D$5-1)*15+12),0) -> 314.62176 | J10: =IFERROR(INDEX(Motor!$F$61:$CP$301,$A10+1,($D$5-1)*15+13),0) -> 151083.7 | K10: =IFERROR(INDEX(Motor!$F$61:$CP$301,$A10+1,($D$5-1)*15+14),0) -> 150590.7 | M10: Linha âmbar: mês em que houve come-cotas (maio e novembro).
A11: 2 | B11: =EDATE(DATA_INICIO,$A11) -> 46318 | C11: =IFERROR(INDEX(Motor!$F$61:$CP$301,$A11+1,($D$5-1)*15+1),0) -> 151398.32 | D11: =IFERROR(INDEX(Motor!$F$61:$CP$301,$A11+1,($D$5-1)*15+4),0) -> 1436.5873 | E11: =IFERROR(INDEX(Motor!$F$61:$CP$301,$A11+1,($D$5-1)*15+2),0) -> 0 | F11: =IFERROR(INDEX(Motor!$F$61:$CP$301,$A11+1,($D$5-1)*15+3)+INDEX(Motor!$F$61:$CP$301,$A11+1,($D$5-1)*15+5)+INDEX(Motor!$F$61:$CP$301,$A11+1,($D$5-1)*15+6),0) -> 25.233053 | G11: =IFERROR(INDEX(Motor!$F$61:$CP$301,$A11+1,($D$5-1)*15+7),0) -> 0 | H11: =IFERROR(INDEX(Motor!$F$61:$CP$301,$A11+1,($D$5-1)*15+8),0) -> 152809.67 | I11: =IFERROR(INDEX(Motor!$F$61:$CP$301,$A11+1,($D$5-1)*15+12),0) -> 632.17647 | J11: =IFERROR(INDEX(Motor!$F$61:$CP$301,$A11+1,($D$5-1)*15+13),0) -> 152177.5 | K11: =IFERROR(INDEX(Motor!$F$61:$CP$301,$A11+1,($D$5-1)*15+14),0) -> 151185.99 | M11: Linha cinza: já passou do prazo escolhido.
A12: 3 | B12: =EDATE(DATA_INICIO,$A12) -> 46349 | C12: =IFERROR(INDEX(Motor!$F$61:$CP$301,$A12+1,($D$5-1)*15+1),0) -> 152809.67 | D12: =IFERROR(INDEX(Motor!$F$61:$CP$301,$A12+1,($D$5-1)*15+4),0) -> 1449.9793 | E12: =IFERROR(INDEX(Motor!$F$61:$CP$301,$A12+1,($D$5-1)*15+2),0) -> 0 | F12: =IFERROR(INDEX(Motor!$F$61:$CP$301,$A12+1,($D$5-1)*15+3)+INDEX(Motor!$F$61:$CP$301,$A12+1,($D$5-1)*15+5)+INDEX(Motor!$F$61:$CP$301,$A12+1,($D$5-1)*15+6),0) -> 25.468279 | G12: =IFERROR(INDEX(Motor!$F$61:$CP$301,$A12+1,($D$5-1)*15+7),0) -> 0 | H12: =IFERROR(INDEX(Motor!$F$61:$CP$301,$A12+1,($D$5-1)*15+8),0) -> 154234.18 | I12: =IFERROR(INDEX(Motor!$F$61:$CP$301,$A12+1,($D$5-1)*15+12),0) -> 952.69146 | J12: =IFERROR(INDEX(Motor!$F$61:$CP$301,$A12+1,($D$5-1)*15+13),0) -> 153281.49 | K12: =IFERROR(INDEX(Motor!$F$61:$CP$301,$A12+1,($D$5-1)*15+14),0) -> 151785.88
A13: 4 | B13: =EDATE(DATA_INICIO,$A13) -> 46379 | C13: =IFERROR(INDEX(Motor!$F$61:$CP$301,$A13+1,($D$5-1)*15+1),0) -> 154234.18 | D13: =IFERROR(INDEX(Motor!$F$61:$CP$301,$A13+1,($D$5-1)*15+4),0) -> 1463.4962 | E13: =IFERROR(INDEX(Motor!$F$61:$CP$301,$A13+1,($D$5-1)*15+2),0) -> 0 | F13: =IFERROR(INDEX(Motor!$F$61:$CP$301,$A13+1,($D$5-1)*15+3)+INDEX(Motor!$F$61:$CP$301,$A13+1,($D$5-1)*15+5)+INDEX(Motor!$F$61:$CP$301,$A13+1,($D$5-1)*15+6),0) -> 25.705697 | G13: =IFERROR(INDEX(Motor!$F$61:$CP$301,$A13+1,($D$5-1)*15+7),0) -> 0 | H13: =IFERROR(INDEX(Motor!$F$61:$CP$301,$A13+1,($D$5-1)*15+8),0) -> 155671.97 | I13: =IFERROR(INDEX(Motor!$F$61:$CP$301,$A13+1,($D$5-1)*15+12),0) -> 1276.1943 | J13: =IFERROR(INDEX(Motor!$F$61:$CP$301,$A13+1,($D$5-1)*15+13),0) -> 154395.78 | K13: =IFERROR(INDEX(Motor!$F$61:$CP$301,$A13+1,($D$5-1)*15+14),0) -> 152390.41
A14: 5 | B14: =EDATE(DATA_INICIO,$A14) -> 46410 | C14: =IFERROR(INDEX(Motor!$F$61:$CP$301,$A14+1,($D$5-1)*15+1),0) -> 155671.97 | D14: =IFERROR(INDEX(Motor!$F$61:$CP$301,$A14+1,($D$5-1)*15+4),0) -> 1477.1391 | E14: =IFERROR(INDEX(Motor!$F$61:$CP$301,$A14+1,($D$5-1)*15+2),0) -> 0 | F14: =IFERROR(INDEX(Motor!$F$61:$CP$301,$A14+1,($D$5-1)*15+3)+INDEX(Motor!$F$61:$CP$301,$A14+1,($D$5-1)*15+5)+INDEX(Motor!$F$61:$CP$301,$A14+1,($D$5-1)*15+6),0) -> 25.945329 | G14: =IFERROR(INDEX(Motor!$F$61:$CP$301,$A14+1,($D$5-1)*15+7),0) -> 0 | H14: =IFERROR(INDEX(Motor!$F$61:$CP$301,$A14+1,($D$5-1)*15+8),0) -> 157123.17 | I14: =IFERROR(INDEX(Motor!$F$61:$CP$301,$A14+1,($D$5-1)*15+12),0) -> 1602.7129 | J14: =IFERROR(INDEX(Motor!$F$61:$CP$301,$A14+1,($D$5-1)*15+13),0) -> 155520.46 | K14: =IFERROR(INDEX(Motor!$F$61:$CP$301,$A14+1,($D$5-1)*15+14),0) -> 152999.6
A15: 6 | B15: =EDATE(DATA_INICIO,$A15) -> 46441 | C15: =IFERROR(INDEX(Motor!$F$61:$CP$301,$A15+1,($D$5-1)*15+1),0) -> 157123.17 | D15: =IFERROR(INDEX(Motor!$F$61:$CP$301,$A15+1,($D$5-1)*15+4),0) -> 1490.9092 | E15: =IFERROR(INDEX(Motor!$F$61:$CP$301,$A15+1,($D$5-1)*15+2),0) -> 0 | F15: =IFERROR(INDEX(Motor!$F$61:$CP$301,$A15+1,($D$5-1)*15+3)+INDEX(Motor!$F$61:$CP$301,$A15+1,($D$5-1)*15+5)+INDEX(Motor!$F$61:$CP$301,$A15+1,($D$5-1)*15+6),0) -> 26.187195 | G15: =IFERROR(INDEX(Motor!$F$61:$CP$301,$A15+1,($D$5-1)*15+7),0) -> 0 | H15: =IFERROR(INDEX(Motor!$F$61:$CP$301,$A15+1,($D$5-1)*15+8),0) -> 158587.89 | I15: =IFERROR(INDEX(Motor!$F$61:$CP$301,$A15+1,($D$5-1)*15+12),0) -> 1932.2754 | J15: =IFERROR(INDEX(Motor!$F$61:$CP$301,$A15+1,($D$5-1)*15+13),0) -> 156655.62 | K15: =IFERROR(INDEX(Motor!$F$61:$CP$301,$A15+1,($D$5-1)*15+14),0) -> 153613.47
A16: 7 | B16: =EDATE(DATA_INICIO,$A16) -> 46469 | C16: =IFERROR(INDEX(Motor!$F$61:$CP$301,$A16+1,($D$5-1)*15+1),0) -> 158587.89 | D16: =IFERROR(INDEX(Motor!$F$61:$CP$301,$A16+1,($D$5-1)*15+4),0) -> 1504.8077 | E16: =IFERROR(INDEX(Motor!$F$61:$CP$301,$A16+1,($D$5-1)*15+2),0) -> 0 | F16: =IFERROR(INDEX(Motor!$F$61:$CP$301,$A16+1,($D$5-1)*15+3)+INDEX(Motor!$F$61:$CP$301,$A16+1,($D$5-1)*15+5)+INDEX(Motor!$F$61:$CP$301,$A16+1,($D$5-1)*15+6),0) -> 26.431315 | G16: =IFERROR(INDEX(Motor!$F$61:$CP$301,$A16+1,($D$5-1)*15+7),0) -> 0 | H16: =IFERROR(INDEX(Motor!$F$61:$CP$301,$A16+1,($D$5-1)*15+8),0) -> 160066.27 | I16: =IFERROR(INDEX(Motor!$F$61:$CP$301,$A16+1,($D$5-1)*15+12),0) -> 2013.2534 | J16: =IFERROR(INDEX(Motor!$F$61:$CP$301,$A16+1,($D$5-1)*15+13),0) -> 158053.01 | K16: =IFERROR(INDEX(Motor!$F$61:$CP$301,$A16+1,($D$5-1)*15+14),0) -> 154478.01
A17: 8 | B17: =EDATE(DATA_INICIO,$A17) -> 46500 | C17: =IFERROR(INDEX(Motor!$F$61:$CP$301,$A17+1,($D$5-1)*15+1),0) -> 160066.27 | D17: =IFERROR(INDEX(Motor!$F$61:$CP$301,$A17+1,($D$5-1)*15+4),0) -> 1518.8357 | E17: =IFERROR(INDEX(Motor!$F$61:$CP$301,$A17+1,($D$5-1)*15+2),0) -> 0 | F17: =IFERROR(INDEX(Motor!$F$61:$CP$301,$A17+1,($D$5-1)*15+3)+INDEX(Motor!$F$61:$CP$301,$A17+1,($D$5-1)*15+5)+INDEX(Motor!$F$61:$CP$301,$A17+1,($D$5-1)*15+6),0) -> 26.677711 | G17: =IFERROR(INDEX(Motor!$F$61:$CP$301,$A17+1,($D$5-1)*15+7),0) -> 0 | H17: =IFERROR(INDEX(Motor!$F$61:$CP$301,$A17+1,($D$5-1)*15+8),0) -> 161558.42 | I17: =IFERROR(INDEX(Motor!$F$61:$CP$301,$A17+1,($D$5-1)*15+12),0) -> 2311.685 | J17: =IFERROR(INDEX(Motor!$F$61:$CP$301,$A17+1,($D$5-1)*15+13),0) -> 159246.74 | K17: =IFERROR(INDEX(Motor!$F$61:$CP$301,$A17+1,($D$5-1)*15+14),0) -> 155136.86
A18: 9 | B18: =EDATE(DATA_INICIO,$A18) -> 46530 | C18: =IFERROR(INDEX(Motor!$F$61:$CP$301,$A18+1,($D$5-1)*15+1),0) -> 161558.42 | D18: =IFERROR(INDEX(Motor!$F$61:$CP$301,$A18+1,($D$5-1)*15+4),0) -> 1532.9944 | E18: =IFERROR(INDEX(Motor!$F$61:$CP$301,$A18+1,($D$5-1)*15+2),0) -> 0 | F18: =IFERROR(INDEX(Motor!$F$61:$CP$301,$A18+1,($D$5-1)*15+3)+INDEX(Motor!$F$61:$CP$301,$A18+1,($D$5-1)*15+5)+INDEX(Motor!$F$61:$CP$301,$A18+1,($D$5-1)*15+6),0) -> 26.926404 | G18: =IFERROR(INDEX(Motor!$F$61:$CP$301,$A18+1,($D$5-1)*15+7),0) -> 0 | H18: =IFERROR(INDEX(Motor!$F$61:$CP$301,$A18+1,($D$5-1)*15+8),0) -> 163064.49 | I18: =IFERROR(INDEX(Motor!$F$61:$CP$301,$A18+1,($D$5-1)*15+12),0) -> 2612.8986 | J18: =IFERROR(INDEX(Motor!$F$61:$CP$301,$A18+1,($D$5-1)*15+13),0) -> 160451.59 | K18: =IFERROR(INDEX(Motor!$F$61:$CP$301,$A18+1,($D$5-1)*15+14),0) -> 155800.57
A19: 10 | B19: =EDATE(DATA_INICIO,$A19) -> 46561 | C19: =IFERROR(INDEX(Motor!$F$61:$CP$301,$A19+1,($D$5-1)*15+1),0) -> 163064.49 | D19: =IFERROR(INDEX(Motor!$F$61:$CP$301,$A19+1,($D$5-1)*15+4),0) -> 1547.2852 | E19: =IFERROR(INDEX(Motor!$F$61:$CP$301,$A19+1,($D$5-1)*15+2),0) -> 0 | F19: =IFERROR(INDEX(Motor!$F$61:$CP$301,$A19+1,($D$5-1)*15+3)+INDEX(Motor!$F$61:$CP$301,$A19+1,($D$5-1)*15+5)+INDEX(Motor!$F$61:$CP$301,$A19+1,($D$5-1)*15+6),0) -> 27.177415 | G19: =IFERROR(INDEX(Motor!$F$61:$CP$301,$A19+1,($D$5-1)*15+7),0) -> 0 | H19: =IFERROR(INDEX(Motor!$F$61:$CP$301,$A19+1,($D$5-1)*15+8),0) -> 164584.6 | I19: =IFERROR(INDEX(Motor!$F$61:$CP$301,$A19+1,($D$5-1)*15+12),0) -> 2916.9201 | J19: =IFERROR(INDEX(Motor!$F$61:$CP$301,$A19+1,($D$5-1)*15+13),0) -> 161667.68 | K19: =IFERROR(INDEX(Motor!$F$61:$CP$301,$A19+1,($D$5-1)*15+14),0) -> 156469.16
A20: 11 | B20: =EDATE(DATA_INICIO,$A20) -> 46591 | C20: =IFERROR(INDEX(Motor!$F$61:$CP$301,$A20+1,($D$5-1)*15+1),0) -> 164584.6 | D20: =IFERROR(INDEX(Motor!$F$61:$CP$301,$A20+1,($D$5-1)*15+4),0) -> 1561.7092 | E20: =IFERROR(INDEX(Motor!$F$61:$CP$301,$A20+1,($D$5-1)*15+2),0) -> 0 | F20: =IFERROR(INDEX(Motor!$F$61:$CP$301,$A20+1,($D$5-1)*15+3)+INDEX(Motor!$F$61:$CP$301,$A20+1,($D$5-1)*15+5)+INDEX(Motor!$F$61:$CP$301,$A20+1,($D$5-1)*15+6),0) -> 27.430767 | G20: =IFERROR(INDEX(Motor!$F$61:$CP$301,$A20+1,($D$5-1)*15+7),0) -> 0 | H20: =IFERROR(INDEX(Motor!$F$61:$CP$301,$A20+1,($D$5-1)*15+8),0) -> 166118.88 | I20: =IFERROR(INDEX(Motor!$F$61:$CP$301,$A20+1,($D$5-1)*15+12),0) -> 3223.7758 | J20: =IFERROR(INDEX(Motor!$F$61:$CP$301,$A20+1,($D$5-1)*15+13),0) -> 162895.1 | K20: =IFERROR(INDEX(Motor!$F$61:$CP$301,$A20+1,($D$5-1)*15+14),0) -> 157142.67
A21: 12 | B21: =EDATE(DATA_INICIO,$A21) -> 46622 | C21: =IFERROR(INDEX(Motor!$F$61:$CP$301,$A21+1,($D$5-1)*15+1),0) -> 166118.88 | D21: =IFERROR(INDEX(Motor!$F$61:$CP$301,$A21+1,($D$5-1)*15+4),0) -> 1576.2676 | E21: =IFERROR(INDEX(Motor!$F$61:$CP$301,$A21+1,($D$5-1)*15+2),0) -> 0 | F21: =IFERROR(INDEX(Motor!$F$61:$CP$301,$A21+1,($D$5-1)*15+3)+INDEX(Motor!$F$61:$CP$301,$A21+1,($D$5-1)*15+5)+INDEX(Motor!$F$61:$CP$301,$A21+1,($D$5-1)*15+6),0) -> 27.68648 | G21: =IFERROR(INDEX(Motor!$F$61:$CP$301,$A21+1,($D$5-1)*15+7),0) -> 0 | H21: =IFERROR(INDEX(Motor!$F$61:$CP$301,$A21+1,($D$5-1)*15+8),0) -> 167667.46 | I21: =IFERROR(INDEX(Motor!$F$61:$CP$301,$A21+1,($D$5-1)*15+12),0) -> 3533.4921 | J21: =IFERROR(INDEX(Motor!$F$61:$CP$301,$A21+1,($D$5-1)*15+13),0) -> 164133.97 | K21: =IFERROR(INDEX(Motor!$F$61:$CP$301,$A21+1,($D$5-1)*15+14),0) -> 157821.12
A22: 13 | B22: =EDATE(DATA_INICIO,$A22) -> 46653 | C22: =IFERROR(INDEX(Motor!$F$61:$CP$301,$A22+1,($D$5-1)*15+1),0) -> 167667.46 | D22: =IFERROR(INDEX(Motor!$F$61:$CP$301,$A22+1,($D$5-1)*15+4),0) -> 1590.9618 | E22: =IFERROR(INDEX(Motor!$F$61:$CP$301,$A22+1,($D$5-1)*15+2),0) -> 0 | F22: =IFERROR(INDEX(Motor!$F$61:$CP$301,$A22+1,($D$5-1)*15+3)+INDEX(Motor!$F$61:$CP$301,$A22+1,($D$5-1)*15+5)+INDEX(Motor!$F$61:$CP$301,$A22+1,($D$5-1)*15+6),0) -> 27.944577 | G22: =IFERROR(INDEX(Motor!$F$61:$CP$301,$A22+1,($D$5-1)*15+7),0) -> 0 | H22: =IFERROR(INDEX(Motor!$F$61:$CP$301,$A22+1,($D$5-1)*15+8),0) -> 169230.48 | I22: =IFERROR(INDEX(Motor!$F$61:$CP$301,$A22+1,($D$5-1)*15+12),0) -> 3365.3336 | J22: =IFERROR(INDEX(Motor!$F$61:$CP$301,$A22+1,($D$5-1)*15+13),0) -> 165865.14 | K22: =IFERROR(INDEX(Motor!$F$61:$CP$301,$A22+1,($D$5-1)*15+14),0) -> 158965.3
A23: 14 | B23: =EDATE(DATA_INICIO,$A23) -> 46683 | C23: =IFERROR(INDEX(Motor!$F$61:$CP$301,$A23+1,($D$5-1)*15+1),0) -> 169230.48 | D23: =IFERROR(INDEX(Motor!$F$61:$CP$301,$A23+1,($D$5-1)*15+4),0) -> 1605.793 | E23: =IFERROR(INDEX(Motor!$F$61:$CP$301,$A23+1,($D$5-1)*15+2),0) -> 0 | F23: =IFERROR(INDEX(Motor!$F$61:$CP$301,$A23+1,($D$5-1)*15+3)+INDEX(Motor!$F$61:$CP$301,$A23+1,($D$5-1)*15+5)+INDEX(Motor!$F$61:$CP$301,$A23+1,($D$5-1)*15+6),0) -> 28.20508 | G23: =IFERROR(INDEX(Motor!$F$61:$CP$301,$A23+1,($D$5-1)*15+7),0) -> 0 | H23: =IFERROR(INDEX(Motor!$F$61:$CP$301,$A23+1,($D$5-1)*15+8),0) -> 170808.07 | I23: =IFERROR(INDEX(Motor!$F$61:$CP$301,$A23+1,($D$5-1)*15+12),0) -> 3641.4115 | J23: =IFERROR(INDEX(Motor!$F$61:$CP$301,$A23+1,($D$5-1)*15+13),0) -> 167166.65 | K23: =IFERROR(INDEX(Motor!$F$61:$CP$301,$A23+1,($D$5-1)*15+14),0) -> 159689.89
... A249: 240 | B249: =EDATE(DATA_INICIO,$A249) -> 53562 | C249: =IFERROR(INDEX(Motor!$F$61:$CP$301,$A249+1,($D$5-1)*15+1),0) -> 1377881.9 | D249: =IFERROR(INDEX(Motor!$F$61:$CP$301,$A249+1,($D$5-1)*15+4),0) -> 13074.436 | E249: =IFERROR(INDEX(Motor!$F$61:$CP$301,$A249+1,($D$5-1)*15+2),0) -> 0 | F249: =IFERROR(INDEX(Motor!$F$61:$CP$301,$A249+1,($D$5-1)*15+3)+INDEX(Motor!$F$61:$CP$301,$A249+1,($D$5-1)*15+5)+INDEX(Motor!$F$61:$CP$301,$A249+1,($D$5-1)*15+6),0) -> 229.64699 | G249: =IFERROR(INDEX(Motor!$F$61:$CP$301,$A249+1,($D$5-1)*15+7),0) -> 0 | H249: =IFERROR(INDEX(Motor!$F$61:$CP$301,$A249+1,($D$5-1)*15+8),0) -> 1390726.7 | I249: =IFERROR(INDEX(Motor!$F$61:$CP$301,$A249+1,($D$5-1)*15+12),0) -> 186109.01 | J249: =IFERROR(INDEX(Motor!$F$61:$CP$301,$A249+1,($D$5-1)*15+13),0) -> 1204617.7 | K249: =IFERROR(INDEX(Motor!$F$61:$CP$301,$A249+1,($D$5-1)*15+14),0) -> 549771.8

Sheet Imovel
A1: COMPRAR UM IMÓVEL PARA ALUGAR
A2: A estratégia do Seu João: comparar aplicação financeira com casa para alugar
A4: 1 · A COMPRA
B5: Incluir o imóvel na comparação? | F5: Sim
B6: Valor do imóvel | F6: 150000
B7: ITBI (% do valor) | F7: 0.02
B8: Escritura e registro (% do valor) | F8: 0.015
B9: ➜ Desembolso total para fechar a compra | F9: =IMOV_VALOR*(1+IMOV_ITBI+IMOV_CARTORIO) -> 155250
B10: =IF(MotorImovel!$B$12<0,"⚠ O cliente tem "&TEXT(IN_CAPITAL,"R$ #,##0")&" e a compra exige "&TEXT(IMOV_DESEMBOLSO,"R$ #,##0")&". Faltam "&TEXT(-MotorImovel!$B$12,"R$ #,##0")&" — quase ninguém lembra dos custos de aquisição, e eles mudam a conta.","✓ O capital disponível cobre o imóvel e os custos de aquisição. A sobra de "&TEXT(MotorImovel!$B$12,"R$ #,##0")&" entra na simulação como caixa aplicado.") -> ⚠ O cliente tem R$ 150,000 e a compra exige R$ 155,250. Faltam R$ 5,250 — quase ninguém lembra dos custos de aquisição, e eles mudam a conta.
